
local ___ = {param2 = 0,name = "air",prob = 254}
local T00 = {param2 = 0,name = "naturalbiomes:acacia_trunk",prob = 254}
local T01 = {param2 = 1,name = "naturalbiomes:acacia_trunk",prob = 254}
local T02 = {param2 = 2,name = "naturalbiomes:acacia_trunk",prob = 254}
local T03 = {param2 = 3,name = "naturalbiomes:acacia_trunk",prob = 254}
local T07 = {param2 = 7,name = "naturalbiomes:acacia_trunk",prob = 254}
local T09 = {param2 = 9,name = "naturalbiomes:acacia_trunk",prob = 254}
local T12 = {param2 = 12,name = "naturalbiomes:acacia_trunk",prob = 254}
local T18 = {param2 = 18,name = "naturalbiomes:acacia_trunk",prob = 254}
local L01 = {param2 = 1,name = "naturalbiomes:acacia_leaves",prob = 254}

return {
	yslice_prob = {
		{ypos = 0,prob = 254},
		{ypos = 1,prob = 254},
		{ypos = 2,prob = 254},
		{ypos = 3,prob = 254},
		{ypos = 4,prob = 254},
		{ypos = 5,prob = 254},
		{ypos = 6,prob = 254},
		{ypos = 7,prob = 254},
		{ypos = 8,prob = 254},
		{ypos = 9,prob = 254},
		{ypos = 10,prob = 254},
		{ypos = 11,prob = 254}
	},
	size = {x = 15,y = 12,z = 15},
	data = {
		___, ___, ___, ___, ___, ___, ___, ___, ___, ___, ___, ___, ___, ___, ___,
		___, ___, ___, ___, ___, ___, ___, ___, ___, ___, ___, ___, ___, ___, ___,
		___, ___, ___, ___, ___, ___, ___, ___, ___, ___, ___, ___, ___, ___, ___,
		___, ___, ___, ___, ___, ___, ___, ___, ___, ___, ___, ___, ___, ___, ___,
		___, ___, ___, ___, ___, ___, ___, ___, ___, ___, ___, ___, ___, ___, ___,
		___, ___, ___, ___, ___, ___, ___, ___, ___, ___, ___, ___, ___, ___, ___,
		___, ___, ___, ___, ___, ___, ___, ___, ___, ___, ___, ___, ___, ___, ___,
		___, ___, ___, ___, ___, ___, ___, L01, ___, ___, ___, ___, ___, ___, ___,
		___, ___, ___, ___, ___, ___, ___, ___, ___, ___, ___, ___, ___, ___, ___,
		___, ___, ___, ___, ___, ___, ___, ___, ___, ___, ___, ___, ___, ___, ___,
		___, ___, ___, ___, ___, ___, ___, ___, ___, ___, ___, ___, ___, ___, ___,
		___, ___, ___, ___, ___, ___, ___, ___, ___, ___, ___, ___, ___, ___, ___,

		___, ___, ___, ___, ___, ___, ___, ___, ___, ___, ___, ___, ___, ___, ___,
		___, ___, ___, ___, ___, ___, ___, ___, ___, ___, ___, ___, ___, ___, ___,
		___, ___, ___, ___, ___, ___, ___, ___, ___, ___, ___, ___, ___, ___, ___,
		___, ___, ___, ___, ___, ___, ___, ___, ___, ___, ___, ___, ___, ___, ___,
		___, ___, ___, ___, ___, ___, ___, ___, ___, ___, ___, ___, ___, ___, ___,
		___, ___, ___, ___, ___, ___, ___, ___, ___, ___, ___, ___, ___, ___, ___,
		___, ___, ___, ___, ___, ___, ___, ___, ___, ___, ___, ___, ___, ___, ___,
		___, ___, ___, ___, ___, ___, L01, L01, L01, ___, ___, ___, ___, ___, ___,
		___, ___, ___, ___, ___, ___, ___, L01, ___, ___, ___, ___, ___, ___, ___,
		___, ___, ___, ___, ___, ___, ___, ___, ___, ___, ___, ___, ___, ___, ___,
		___, ___, ___, ___, ___, ___, ___, ___, ___, ___, ___, ___, ___, ___, ___,
		___, ___, ___, ___, ___, ___, ___, ___, ___, ___, ___, ___, ___, ___, ___,

		___, ___, ___, ___, ___, ___, ___, ___, ___, ___, ___, ___, ___, ___, ___,
		___, ___, ___, ___, ___, ___, ___, ___, ___, ___, ___, ___, ___, ___, ___,
		___, ___, ___, ___, ___, ___, ___, ___, ___, ___, ___, ___, ___, ___, ___,
		___, ___, ___, ___, ___, ___, ___, ___, ___, ___, ___, ___, ___, ___, ___,
		___, ___, ___, ___, ___, ___, ___, ___, ___, ___, ___, ___, ___, ___, ___,
		___, ___, ___, ___, ___, ___, ___, ___, ___, ___, ___, ___, ___, ___, ___,
		___, ___, ___, ___, ___, ___, ___, T09, ___, ___, ___, ___, ___, ___, ___,
		___, ___, ___, ___, ___, L01, L01, L01, L01, L01, ___, ___, ___, ___, ___,
		___, ___, ___, ___, ___, ___, L01, L01, L01, ___, ___, ___, ___, ___, ___,
		___, ___, ___, ___, ___, ___, ___, ___, ___, ___, ___, ___, ___, ___, ___,
		___, ___, ___, ___, ___, ___, ___, ___, ___, ___, ___, ___, ___, ___, ___,
		___, ___, ___, ___, ___, ___, ___, ___, ___, ___, ___, ___, ___, ___, ___,

		___, ___, ___, ___, ___, ___, ___, ___, ___, ___, ___, ___, ___, ___, ___,
		___, ___, ___, ___, ___, ___, ___, ___, ___, ___, ___, ___, ___, ___, ___,
		___, ___, ___, ___, ___, ___, ___, ___, ___, ___, ___, ___, ___, ___, ___,
		___, ___, ___, ___, ___, ___, ___, ___, ___, ___, ___, ___, ___, ___, ___,
		___, ___, ___, ___, ___, ___, ___, ___, ___, ___, ___, ___, ___, ___, ___,
		___, ___, ___, ___, ___, ___, ___, ___, ___, ___, ___, ___, ___, ___, ___,
		___, ___, ___, ___, ___, ___, ___, T09, ___, ___, ___, ___, ___, ___, ___,
		___, ___, ___, ___, L01, L01, L01, L01, L01, L01, L01, ___, ___, ___, ___,
		___, ___, ___, ___, ___, L01, L01, L01, L01, L01, ___, ___, ___, ___, ___,
		___, ___, ___, ___, ___, ___, ___, L01, ___, ___, ___, ___, ___, ___, ___,
		___, ___, ___, ___, ___, ___, ___, ___, ___, ___, ___, ___, ___, ___, ___,
		___, ___, ___, ___, ___, ___, ___, ___, ___, ___, ___, ___, ___, ___, ___,

		___, ___, ___, ___, ___, ___, ___, ___, ___, ___, ___, ___, ___, ___, ___,
		___, ___, ___, ___, ___, ___, ___, ___, ___, ___, ___, ___, ___, ___, ___,
		___, ___, ___, ___, ___, ___, ___, ___, ___, ___, ___, ___, ___, ___, ___,
		___, ___, ___, ___, ___, ___, ___, ___, ___, ___, ___, ___, ___, ___, ___,
		___, ___, ___, ___, ___, ___, ___, ___, ___, ___, ___, ___, ___, ___, ___,
		___, ___, ___, ___, ___, ___, ___, ___, ___, ___, ___, ___, ___, ___, ___,
		___, ___, ___, ___, ___, ___, ___, T09, ___, ___, ___, ___, ___, ___, ___,
		___, ___, ___, L01, L01, L01, L01, L01, L01, L01, L01, L01, ___, ___, ___,
		___, ___, ___, ___, L01, L01, L01, L01, L01, L01, L01, ___, ___, ___, ___,
		___, ___, ___, ___, ___, ___, L01, L01, L01, ___, ___, ___, ___, ___, ___,
		___, ___, ___, ___, ___, ___, ___, ___, ___, ___, ___, ___, ___, ___, ___,
		___, ___, ___, ___, ___, ___, ___, ___, ___, ___, ___, ___, ___, ___, ___,

		___, ___, ___, ___, ___, ___, ___, ___, ___, ___, ___, ___, ___, ___, ___,
		___, ___, ___, ___, ___, ___, ___, ___, ___, ___, ___, ___, ___, ___, ___,
		___, ___, ___, ___, ___, ___, ___, ___, ___, ___, ___, ___, ___, ___, ___,
		___, ___, ___, ___, ___, ___, ___, ___, ___, ___, ___, ___, ___, ___, ___,
		___, ___, ___, ___, ___, ___, ___, T09, ___, ___, ___, ___, ___, ___, ___,
		___, ___, ___, ___, ___, ___, ___, T01, ___, ___, ___, ___, ___, ___, ___,
		___, ___, ___, ___, ___, ___, ___, T03, ___, ___, ___, ___, ___, ___, ___,
		___, ___, L01, L01, L01, L01, L01, L01, L01, L01, L01, L01, L01, ___, ___,
		___, ___, ___, L01, L01, L01, L01, L01, L01, L01, L01, L01, ___, ___, ___,
		___, ___, ___, ___, ___, L01, L01, L01, L01, L01, L01, ___, ___, ___, ___,
		___, ___, ___, ___, ___, ___, ___, ___, ___, ___, ___, ___, ___, ___, ___,
		___, ___, ___, ___, ___, ___, ___, ___, ___, ___, ___, ___, ___, ___, ___,

		___, ___, ___, ___, ___, ___, ___, ___, ___, ___, ___, ___, ___, ___, ___,
		___, ___, ___, ___, ___, ___, ___, ___, ___, ___, ___, ___, ___, ___, ___,
		___, ___, ___, ___, ___, ___, ___, ___, ___, ___, ___, ___, ___, ___, ___,
		___, ___, ___, ___, ___, ___, ___, ___, ___, ___, ___, ___, ___, ___, ___,
		___, ___, ___, ___, ___, ___, ___, T09, ___, ___, ___, ___, ___, ___, ___,
		___, ___, ___, ___, ___, ___, ___, ___, ___, ___, ___, ___, ___, ___, ___,
		___, ___, ___, ___, ___, ___, ___, ___, ___, ___, ___, ___, ___, ___, ___,
		___, L01, L01, L01, L01, L01, L01, L01, L01, L01, L01, L01, L01, L01, ___,
		___, ___, L01, L01, L01, L01, L01, L01, L01, L01, L01, L01, L01, ___, ___,
		___, ___, ___, ___, L01, L01, L01, L01, L01, L01, L01, ___, ___, ___, ___,
		___, ___, ___, ___, ___, ___, ___, L01, ___, ___, ___, ___, ___, ___, ___,
		___, ___, ___, ___, ___, ___, ___, ___, ___, ___, ___, ___, ___, ___, ___,

		___, ___, ___, ___, ___, ___, ___, T02, ___, ___, ___, ___, ___, ___, ___,
		___, ___, ___, ___, ___, ___, ___, T02, ___, ___, ___, ___, ___, ___, ___,
		___, ___, ___, ___, ___, ___, ___, T02, ___, ___, ___, ___, ___, ___, ___,
		___, ___, ___, ___, ___, ___, ___, T02, ___, ___, ___, ___, ___, ___, ___,
		___, ___, ___, ___, ___, T18, T18, T02, T12, T12, ___, ___, ___, ___, ___,
		___, ___, ___, ___, ___, T00, ___, ___, ___, T03, ___, ___, ___, ___, ___,
		___, ___, T18, T18, T18, T02, ___, ___, ___, T00, T12, T12, T12, ___, ___,
		L01, L01, L01, L01, L01, L01, L01, L01, L01, L01, L01, L01, L01, L01, L01,
		___, L01, L01, L01, L01, L01, L01, L01, L01, L01, L01, L01, L01, L01, ___,
		___, ___, ___, L01, L01, L01, L01, L01, L01, L01, L01, L01, ___, ___, ___,
		___, ___, ___, ___, ___, ___, L01, L01, L01, ___, ___, ___, ___, ___, ___,
		___, ___, ___, ___, ___, ___, ___, ___, ___, ___, ___, ___, ___, ___, ___,

		___, ___, ___, ___, ___, ___, ___, ___, ___, ___, ___, ___, ___, ___, ___,
		___, ___, ___, ___, ___, ___, ___, ___, ___, ___, ___, ___, ___, ___, ___,
		___, ___, ___, ___, ___, ___, ___, ___, ___, ___, ___, ___, ___, ___, ___,
		___, ___, ___, ___, ___, ___, ___, ___, ___, ___, ___, ___, ___, ___, ___,
		___, ___, ___, ___, ___, ___, ___, T07, ___, ___, ___, ___, ___, ___, ___,
		___, ___, ___, ___, ___, ___, ___, ___, ___, ___, ___, ___, ___, ___, ___,
		___, ___, ___, ___, ___, ___, ___, ___, ___, ___, ___, ___, ___, ___, ___,
		___, L01, L01, L01, L01, L01, L01, L01, L01, L01, L01, L01, L01, L01, ___,
		___, ___, L01, L01, L01, L01, L01, L01, L01, L01, L01, L01, L01, ___, ___,
		___, ___, ___, ___, L01, L01, L01, L01, L01, L01, L01, ___, ___, ___, ___,
		___, ___, ___, ___, ___, ___, ___, L01, ___, ___, ___, ___, ___, ___, ___,
		___, ___, ___, ___, ___, ___, ___, ___, ___, ___, ___, ___, ___, ___, ___,

		___, ___, ___, ___, ___, ___, ___, ___, ___, ___, ___, ___, ___, ___, ___,
		___, ___, ___, ___, ___, ___, ___, ___, ___, ___, ___, ___, ___, ___, ___,
		___, ___, ___, ___, ___, ___, ___, ___, ___, ___, ___, ___, ___, ___, ___,
		___, ___, ___, ___, ___, ___, ___, ___, ___, ___, ___, ___, ___, ___, ___,
		___, ___, ___, ___, ___, ___, ___, T07, ___, ___, ___, ___, ___, ___, ___,
		___, ___, ___, ___, ___, ___, ___, T01, ___, ___, ___, ___, ___, ___, ___,
		___, ___, ___, ___, ___, ___, ___, T03, ___, ___, ___, ___, ___, ___, ___,
		___, ___, L01, L01, L01, L01, L01, L01, L01, L01, L01, L01, L01, ___, ___,
		___, ___, ___, L01, L01, L01, L01, L01, L01, L01, L01, L01, ___, ___, ___,
		___, ___, ___, ___, ___, L01, L01, L01, L01, L01, ___, ___, ___, ___, ___,
		___, ___, ___, ___, ___, ___, ___, ___, ___, ___, ___, ___, ___, ___, ___,
		___, ___, ___, ___, ___, ___, ___, ___, ___, ___, ___, ___, ___, ___, ___,

		___, ___, ___, ___, ___, ___, ___, ___, ___, ___, ___, ___, ___, ___, ___,
		___, ___, ___, ___, ___, ___, ___, ___, ___, ___, ___, ___, ___, ___, ___,
		___, ___, ___, ___, ___, ___, ___, ___, ___, ___, ___, ___, ___, ___, ___,
		___, ___, ___, ___, ___, ___, ___, ___, ___, ___, ___, ___, ___, ___, ___,
		___, ___, ___, ___, ___, ___, ___, ___, ___, ___, ___, ___, ___, ___, ___,
		___, ___, ___, ___, ___, ___, ___, ___, ___, ___, ___, ___, ___, ___, ___,
		___, ___, ___, ___, ___, ___, ___, T07, ___, ___, ___, ___, ___, ___, ___,
		___, ___, ___, L01, L01, L01, L01, L01, L01, L01, L01, L01, ___, ___, ___,
		___, ___, ___, ___, L01, L01, L01, L01, L01, L01, L01, ___, ___, ___, ___,
		___, ___, ___, ___, ___, ___, L01, L01, L01, ___, ___, ___, ___, ___, ___,
		___, ___, ___, ___, ___, ___, ___, ___, ___, ___, ___, ___, ___, ___, ___,
		___, ___, ___, ___, ___, ___, ___, ___, ___, ___, ___, ___, ___, ___, ___,

		___, ___, ___, ___, ___, ___, ___, ___, ___, ___, ___, ___, ___, ___, ___,
		___, ___, ___, ___, ___, ___, ___, ___, ___, ___, ___, ___, ___, ___, ___,
		___, ___, ___, ___, ___, ___, ___, ___, ___, ___, ___, ___, ___, ___, ___,
		___, ___, ___, ___, ___, ___, ___, ___, ___, ___, ___, ___, ___, ___, ___,
		___, ___, ___, ___, ___, ___, ___, ___, ___, ___, ___, ___, ___, ___, ___,
		___, ___, ___, ___, ___, ___, ___, ___, ___, ___, ___, ___, ___, ___, ___,
		___, ___, ___, ___, ___, ___, ___, T07, ___, ___, ___, ___, ___, ___, ___,
		___, ___, ___, ___, L01, L01, L01, L01, L01, L01, L01, ___, ___, ___, ___,
		___, ___, ___, ___, ___, L01, L01, L01, L01, L01, ___, ___, ___, ___, ___,
		___, ___, ___, ___, ___, ___, ___, L01, ___, ___, ___, ___, ___, ___, ___,
		___, ___, ___, ___, ___, ___, ___, ___, ___, ___, ___, ___, ___, ___, ___,
		___, ___, ___, ___, ___, ___, ___, ___, ___, ___, ___, ___, ___, ___, ___,

		___, ___, ___, ___, ___, ___, ___, ___, ___, ___, ___, ___, ___, ___, ___,
		___, ___, ___, ___, ___, ___, ___, ___, ___, ___, ___, ___, ___, ___, ___,
		___, ___, ___, ___, ___, ___, ___, ___, ___, ___, ___, ___, ___, ___, ___,
		___, ___, ___, ___, ___, ___, ___, ___, ___, ___, ___, ___, ___, ___, ___,
		___, ___, ___, ___, ___, ___, ___, ___, ___, ___, ___, ___, ___, ___, ___,
		___, ___, ___, ___, ___, ___, ___, ___, ___, ___, ___, ___, ___, ___, ___,
		___, ___, ___, ___, ___, ___, ___, T07, ___, ___, ___, ___, ___, ___, ___,
		___, ___, ___, ___, ___, L01, L01, L01, L01, ___, ___, ___, ___, ___, ___,
		___, ___, ___, ___, ___, ___, L01, L01, L01, ___, ___, ___, ___, ___, ___,
		___, ___, ___, ___, ___, ___, ___, ___, ___, ___, ___, ___, ___, ___, ___,
		___, ___, ___, ___, ___, ___, ___, ___, ___, ___, ___, ___, ___, ___, ___,
		___, ___, ___, ___, ___, ___, ___, ___, ___, ___, ___, ___, ___, ___, ___,

		___, ___, ___, ___, ___, ___, ___, ___, ___, ___, ___, ___, ___, ___, ___,
		___, ___, ___, ___, ___, ___, ___, ___, ___, ___, ___, ___, ___, ___, ___,
		___, ___, ___, ___, ___, ___, ___, ___, ___, ___, ___, ___, ___, ___, ___,
		___, ___, ___, ___, ___, ___, ___, ___, ___, ___, ___, ___, ___, ___, ___,
		___, ___, ___, ___, ___, ___, ___, ___, ___, ___, ___, ___, ___, ___, ___,
		___, ___, ___, ___, ___, ___, ___, ___, ___, ___, ___, ___, ___, ___, ___,
		___, ___, ___, ___, ___, ___, ___, ___, ___, ___, ___, ___, ___, ___, ___,
		___, ___, ___, ___, ___, ___, L01, L01, L01, ___, ___, ___, ___, ___, ___,
		___, ___, ___, ___, ___, ___, ___, L01, ___, ___, ___, ___, ___, ___, ___,
		___, ___, ___, ___, ___, ___, ___, ___, ___, ___, ___, ___, ___, ___, ___,
		___, ___, ___, ___, ___, ___, ___, ___, ___, ___, ___, ___, ___, ___, ___,
		___, ___, ___, ___, ___, ___, ___, ___, ___, ___, ___, ___, ___, ___, ___,

		___, ___, ___, ___, ___, ___, ___, ___, ___, ___, ___, ___, ___, ___, ___,
		___, ___, ___, ___, ___, ___, ___, ___, ___, ___, ___, ___, ___, ___, ___,
		___, ___, ___, ___, ___, ___, ___, ___, ___, ___, ___, ___, ___, ___, ___,
		___, ___, ___, ___, ___, ___, ___, ___, ___, ___, ___, ___, ___, ___, ___,
		___, ___, ___, ___, ___, ___, ___, ___, ___, ___, ___, ___, ___, ___, ___,
		___, ___, ___, ___, ___, ___, ___, ___, ___, ___, ___, ___, ___, ___, ___,
		___, ___, ___, ___, ___, ___, ___, ___, ___, ___, ___, ___, ___, ___, ___,
		___, ___, ___, ___, ___, ___, ___, L01, ___, ___, ___, ___, ___, ___, ___,
		___, ___, ___, ___, ___, ___, ___, ___, ___, ___, ___, ___, ___, ___, ___,
		___, ___, ___, ___, ___, ___, ___, ___, ___, ___, ___, ___, ___, ___, ___,
		___, ___, ___, ___, ___, ___, ___, ___, ___, ___, ___, ___, ___, ___, ___,
		___, ___, ___, ___, ___, ___, ___, ___, ___, ___, ___, ___, ___, ___, ___
	}
}